Workbook
Name _Sol25: input!$L$183
Name aA.tot: engine!$DI$168:$DO$168
Name aC.tot: engine!$AU$168:$BA$168
Name ADSORB.w1C.sd1C: continental!$L$175
Name ADSORB.w1R.sd1R: regional!$L$169
Name ADSORB.w2C.sd2C: continental!$L$177
Name ADSORB.w2R.sd2R: regional!$L$171
Name ADSORB.w3A.sdA: global!$L$435
Name ADSORB.w3M.sdM: global!$L$113
Name ADSORB.w3T.sdT: global!$L$757
Name ADSORBflow.w1R.sd1R: regional!$L$169
Name ADSORBflow.w2R.sd2R: regional!$L$171
Name ADSORBflow.w3M.sdM: global!$L$113
Name AEROresist.s1C: continental!$L$397
Name AEROresist.s1R: regional!$L$391
Name AEROresist.s2C: continental!$L$408
Name AEROresist.s2R: regional!$L$402
Name AEROresist.s3C: continental!$L$419
Name AEROresist.s3R: regional!$L$413
Name AEROresist.sA: global!$L$585
Name AEROresist.sM: global!$L$264
Name AEROresist.sT: global!$L$907
Name AEROresist.w0C: continental!$L$451
Name AEROresist.w0R: regional!$L$445
Name AEROresist.w1C: continental!$L$458
Name AEROresist.w1R: regional!$L$452
Name AEROresist.w2A: global!$L$603
Name AEROresist.w2C: continental!$L$461
Name AEROresist.w2M: global!$L$282
Name AEROresist.w2R: regional!$L$455
Name AEROresist.w2T: global!$L$925
Name AEROSOLdeprate.A: global!$L$413
Name AEROSOLdeprate.C: continental!$L$136
Name AEROSOLdeprate.M: global!$L$91
Name AEROSOLdeprate.R: regional!$L$130
Name AEROSOLdeprate.T: global!$L$735
Name AerosolWashout.A: global!$L$411
Name AerosolWashout.C: continental!$L$134
Name AerosolWashout.M: global!$L$89
Name AerosolWashout.R: regional!$L$128
Name AerosolWashout.T: global!$L$733
Name AHamakerSP.w: input!$L$16
Name aM.tot: engine!$CL$168:$CR$168
Name aR.tot: engine!$D$168:$J$168
Name AREAFRAC.s1C: continental!$L$19
Name AREAFRAC.s1R: regional!$L$19
Name AREAFRAC.s2C: continental!$L$20
Name AREAFRAC.s2R: regional!$L$20
Name AREAFRAC.s3C: continental!$L$21
Name AREAFRAC.s3R: regional!$L$21
Name AREAFRAC.sA: global!$L$342
Name AREAFRAC.sM: global!$L$13
Name AREAFRAC.sT: global!$L$664
Name AREAFRAC.w0C: continental!$L$17
Name AREAFRAC.w0R: regional!$L$17
Name AREAFRAC.w1C: continental!$L$18
Name AREAFRAC.w1R: regional!$L$18
Name AREAFRAC.w2C: continental!$L$22
Name AREAFRAC.w2R: regional!$L$22
Name AREAFRAC.wA: global!$L$341

Sheet version
B2: SimpleBox4plastics
B3: =C26 -> vs 4.04-plastic | C3: =B26 -> 45387
B4: www.rivm.nl
B6: Contact
B7: JTK Quik
B8: National Institute of Public Health and the Environment (RIVM)
B9: Post Box 1, 3720BA Bilthoven, The Netherlands
B10: joris.quik@rivm.nl
B13: References SimpleBox4plastic
B14: JTK Quik et al. A multimedia model for microplastic particles. (2023) A multimedia model to estimate environmental fate of microplastic particles. Science of The Total Environment 163437. https://doi.org/10.1016/j.scitotenv.2023.163437
B15: J. Meesters et al. A Model Sensitivity Analysis to Determine the Most Important Physicochemical Properties Driving Environmental Fate and Exposure of Engineered Nanoparticles. Environ. Sci.: Nano 2019, 6, (7), 2049-2060
B16: J. Meesters et al. Multimedia Environmental Fate and Speciation of Engineered Nanoparticles: A Probabilistic Modeling Approach. Environ. Sci.: Nano 2016, 3, (4), 715-727.
B17: J. Meesters et al. SimpleBox4nano model definition: Multimedia Modeling of Engineered Nanoparticles with SimpleBox4nano: Model Definition and Evaluation (2014) ES&T 48(10), 5726-5736
B18: Reference SimpleBox
... B25: Modifications log
B26: 45387 | C26: vs 4.04-plastic | D26: [Fix] 'Runoff was not being input to lake water (Regional and Continental). This is now implemented based on fraction surface area of W0 and W1
E27: See changes for k.s1.w0C/R, k.s2.w0C/R, k.s3.w0C/R and .......w1. include the surface area correction
E28: Take care that the cases related to comparison to SimpleBox v3.32 are not updated
E29: The all species output tables and graphics are NOT updated based on this fix, so they are not complete
D30: [Fix] 'in the regional scale: calculation of runoff for agricultural soil was related to FRACrun.s1R instead of FRACrun.s2R
D31: [fix] FRgas.Aa used variable from Moderate scale.
D32: [fix] Waterflow from w0R to W1R should be 10% of flow to the sea (w2) of freshwater (w1)
D33: [Fix] 'In the continental scale: calculation of FRs.sx for the three soil types (natural, agricultural, other), all used the Kp for natural soil,
E34: instead of the one corresponding to the soil type. Changed to soiltype specific Kp. Formulas were already correct at regional scale
D35: [Fix] formula for variables Fraers.aA and Fraerw.aA incorrectly used variables for Moderate scale instead of Arctic scale. This was fixed
B37: 45338 | C37: vs 4.02-plastic | D37: [fix] Flow of w1 to w0 was not implemented in the engine
D38: [Known issue] surface runoff from soils to lakewater is missing
B39: 44876 | C39: vs 4.02-plastic | D39: [improvement] Added degradatation and fragmentation as separate processes for particles, aimed at polymers [input]
D40: [improvement] added mass flow table for particle species [all species output]
D41: [improvement] smal layout and textual changes
D42: [fix] waterflow from w1C to w1R and RainRate.R from conv. SB4
D43: [fix] naming and refs of kdegG.air, KDEG.aA and particle degradation rate constants. Clash with conv. SB4. [regional/continental/global]
D44: [fix] use cellnames instead of cell refs (several, e.g. kdegS/A/P and COL/SUSP)
D45: [fix] missing flow from w1C to w1R for SAP species
D46: [fix] percentage mass in soils at contiental scale in all species output sheet
D47: [change] calculation of input arealand.C and areasea.C and SYSTEMAREA.C
D48: [added] case for not using regional scale (only C and global scales)
B50: 44266 | C50: vs 4.01-nano | D50: [improvement] minor improvements (link to dynamic R script)
D51: [fix] formula AerosolWashout.T
B52: 44139 | C52: vs 4.01-nano | D52: [bugfix] aerosol wahsout for P species (k.a*P.cw*P) was dependant on Fraers.a*. This is not the case, as all P is particulate/solid.
...

Sheet all species output
B2: Output table 1: Steady-state Concentrations, Fugacities, Emissions and Mass | AA2: Output table 2: Steady-state mass flows for D species only (kg.s-1) | AT2: Table 2: Steady-state mass flows (ton.yr-1) | BN2: Graphic output (D species only): Steady-state mass flows (kg.s-1) | BT2: Substance: | BU2: =ChemName -> default substance | BW2: Model | BX2: =CONCATENATE(version!$B$2," ",version!$B$3," ",version!$C$3) -> SimpleBox4plastics vs 4.04-plastic 45387
BN3: REGIONAL SCALE | BW3: Date | BX3: =TODAY() -> 45387
B4: Model | C4: =CONCATENATE(version!$B$2," ",version!$B$3," ",version!$C$3) -> SimpleBox4plastics vs 4.04-plastic 45387 | AA4: Model | AB4: =CONCATENATE(version!$B$2," ",version!$B$3," ",version!$C$3) -> SimpleBox4plastics vs 4.04-plastic 45387 | AT4: Model | AU4: SimpleBox version 3.9 | CD4: =AF12 -> 0
B5: Substance | C5: =ChemName -> default substance | AA5: Substance | AB5: =ChemName -> default substance | AT5: Substance | AU5: median substance
B6: Scenario | C6: =ScenarioName -> default scenario | AA6: Scenario | AB6: =ScenarioName -> default scenario | AT6: Scenario | AU6: Default SimpleBox
B7: Case | C7: =CaseName -> defaults only | AA7: Case | AB7: =CaseName -> defaults only | AT7: Case | AU7: SimpleBox version 3.31 | BS7: Air: | BT7: =IF(ISERROR(D12),0,D12) -> 0
C9: Masses (kg) | M9: Concentrations | S9: Fugacities (Pa) | AA9: Dissolved species | AC9: Emission | AD9: Inflow | AE9: Outflow | AF9: Removal | AG9: Formation (S,A,P->D) | AH9: Degradation | AI9: air-water | AJ9: water-air | AK9: air-soil | AL9: soil-air | AM9: soil-water | AN9: water-sed | AO9: sed-water | AP9: mass | AU9: aR | AV9: w1R | AW9: w2R | AX9: sd1R | AY9: sd2R | AZ9: s1R | BA9: s2R | BB9: s3R | BC9: aC | BD9: w1C | BE9: w2C | BF9: sd1C | BG9: sd2C | BH9: s1C | BI9: s2C | BJ9: s3C | BN9: C | BP9: =AD12 -> 0
C10: Reg | E10: Cont | G10: Mod | I10: Arct | K10: Trop | M10: Reg | N10: Cont | O10: Mod | P10: Arct | Q10: Trop | S10: Reg | T10: Cont | U10: Mod | V10: Arct | W10: Trop | AI10: transport | AJ10: transport | AK10: transport | AL10: transport | AM10: transport | AN10: transport | AO10: transport | AP10: balance | BN10: =AE12 -> 0 | BP10: C | BY10: / / / / / / / / / /
B11: Air | C11: =SUM(C12,C15:C17) -> 34306.845 | D11: =C11/$C$103 -> 2.0734805e-06 | E11: =SUM(E12,E15:E17) -> 125031.33 | F11: =E11/$E$103 -> 3.8128611e-06 | G11: =SUM(G12,G15:G17) -> 77588.164 | H11: =G11/$G$103 -> 1.4999892e-08 | I11: =SUM(I12,I15:I17) -> 15994.048 | J11: =I11/$I$103 -> 4.678366e-09 | K11: =SUM(K12,K15:K17) -> 23835.438 | L11: =K11/$K$103 -> 1.8649116e-09 | M11: =(M.aRG+M.aRS+M.aRA+M.aRP+M.cwRS+M.cwRA+M.cwRP)*(Molweight*1000)/(VOLUME.aR+VOLUME.cwR) -> 1.4943958e-07 | N11: =(M.aCG+M.aCS+M.aCA+M.aCP+M.cwCS+M.cwCA+M.cwCP)*Molweight*1000/(VOLUME.aC+VOLUME.cwC) -> 1.7367271e-08 | O11: =(M.aMG+M.aMS+M.aMA+M.aMP+M.cwMS+M.cwMA+M.cwMP)*Molweight*1000/(VOLUME.aM+VOLUME.cwM) -> 1.0002189e-09 | P11: =(M.aAG+M.aAS+M.aAA+M.aAP+M.cwAS+M.cwAA+M.cwAP)*Molweight*1000/(VOLUME.aA+VOLUME.cwA) -> 3.7633055e-10 | Q11: =(M.aTG+M.aTS+M.aTA+M.aTP+M.cwTS+M.cwTA+M.cwTP)*Molweight*1000/(VOLUME.aT+VOLUME.cwT) -> 1.8694461e-10 | R11: g.m-3 | AA11: Regional Scale | AT11: Emission | BY11: / / / / / / / / / /
B12: Dissolved/Gas species (G/D) | C12: =(M.aRG)*Molweight -> 0 | D12: =C12/$C$103 -> 0 | E12: =(M.aCG)*Molweight -> 0 | F12: =E12/$E$103 -> 0 | G12: =(M.aMG)*Molweight -> 0 | H12: =G12/$G$103 -> 0 | I12: =(M.aAG)*Molweight -> 0 | J12: =I12/$I$103 -> 0 | K12: =(M.aTG)*Molweight -> 0 | L12: =K12/$K$103 -> 0 | M12: =(M.aRG)*(Molweight*1000)/(VOLUME.aR + VOLUME.cwR) -> 0 | N12: =(M.aCG)*(Molweight*1000)/(VOLUME.aC + VOLUME.cwC) -> 0 | O12: =(M.aMG)*(Molweight*1000)/(VOLUME.aM + VOLUME.cwM) -> 0 | P12: =(M.aAG)*(Molweight*1000)/(VOLUME.aA + VOLUME.cwA) -> 0 | Q12: =(M.aTG)*(Molweight*1000)/(VOLUME.aT + VOLUME.cwT) -> 0 | R12: g.m-3 | S12: =F.aR -> 0 | T12: =F.aC -> 0 | U12: =F.aM -> 0 | V12: =F.aA -> 0 | W12: =F.aT -> 0 | AA12: air | AB12: aR | AC12: =E.aRG*Molweight -> 0 | AD12: =k.aC.aR*M.aC*Molweight -> 0 | AE12: =k.aR.aC*M.aR*Molweight -> 0 | AF12: =kesc.aR*VOLUME.aR*C.aRG*Molweight -> 0 | AH12: =KDEG.aR*VOLUME.aR*C.aR*Molweight -> 0 | AI12: =SUM(AI13:AI15,AK18:AK20) -> 0 | AJ12: =SUM(AJ13:AJ15,AL18:AL20) -> 0 | AP12: =SUM(AC12,AD12,AJ12,AL12)-SUM(AE12,AF12,AH12,AI12,AK12) -> 0 | BR12: =AH12 -> 0
B13: * GAS PHASE | C13: =FRgas.aR*C12 -> 0 | D13: =C13/$C$103 -> 0 | E13: =FRgas.aC*E12 -> 0 | F13: =E13/$E$103 -> 0 | G13: =FRgas.aC*G12 -> 0 | H13: =G13/$G$103 -> 0 | I13: =FRgas.aC*I12 -> 0 | J13: =I13/$I$103 -> 0 | K13: =FRgas.aC*K12 -> 0 | L13: =K13/$K$103 -> 0 | M13: =FRgas.aR*M12 -> 0 | N13: =FRgas.aC*N12 -> 0 | O13: =FRgas.aM*O12 -> 0 | P13: =FRgas.aA*P12 -> 0 | Q13: =FRgas.aT*Q12 -> 0 | R13: g.m-3 | S13: =S12*FRgas.aR -> 0 | T13: =T12*FRgas.aC -> 0 | U13: =U12*FRgas.aM -> 0 | V13: =V12*FRgas.aA -> 0 | W13: =W12*FRgas.aT -> 0 | AA13: fresh water lakes | AB13: w0R | AC13: =E.w0RD*Molweight -> 0 | AD13: =k.w1R.w0R*M.w1RD*Molweight -> 0 | AE13: =(k.w0R.w1R+k.w0R.w2R)*M.w0RD*Molweight -> 0 | AG13: =(kdis.w0S.w0D*M.w0RS+kdis.w0A.w0D*M.w0RA+kdis.w0P.w0D*M.w0RP)*Molweight -> 0 | AH13: =KDEG.w0R*M.w0RD*Molweight -> 0 | AI13: =k.aRG.w0RD*M.aRG*Molweight -> 0 | AJ13: =k.w0RD.aRG*M.w0R*Molweight -> 0 | AN13: =k.w0RD.sd0RD*M.w0RD*Molweight -> 0 | AO13: =k.sd0RD.w0RD*M.sd0RD*Molweight -> 0 | AP13: =SUM(AC13,AD13,AI13,AM13,AO13,AG13)-SUM(AF13,AE13,AH13,AJ13,AN13) -> 0 | AT13: Inflow | BP13: =AC12 -> 0
B14: * AEROSOL- and CLOUD PHASES | C14: =(1-FRgas.aR)*C12 -> 0 | D14: =C14/$C$103 -> 0 | E14: =(1-FRgas.aC)*E12 -> 0 | F14: =E14/$E$103 -> 0 | G14: =(1-FRgas.aC)*G12 -> 0 | H14: =G14/$G$103 -> 0 | I14: =(1-FRgas.aC)*I12 -> 0 | J14: =I14/$I$103 -> 0 | K14: =(1-FRgas.aC)*K12 -> 0 | L14: =K14/$K$103 -> 0 | M14: =(1-FRgas.aR)*M12 -> 0 | N14: =(1-FRgas.aC)*N12 -> 0 | O14: =(1-FRgas.aM)*O12 -> 0 | P14: =(1-FRgas.aA)*P12 -> 0 | Q14: =(1-FRgas.aT)*Q12 -> 0 | R14: g.m-3 | S14: =S12*(1-FRgas.aR) -> 0 | T14: =T12*(1-FRgas.aC) -> 0 | U14: =U12*(1-FRgas.aM) -> 0 | V14: =V12*(1-FRgas.aA) -> 0 | W14: =W12*(1-FRgas.aT) -> 0 | AA14: fresh water | AB14: w1R | AC14: =E.w1RD*Molweight -> 0 | AD14: =(WATERflow.w0R.w1R*C.w0R+WATERflow.w1C.w1R*C.w1C)*Molweight -> 0 | AE14: =(WATERflow.w1R.w0R+WATERflow.w1R.w2R)*C.w1R*Molweight -> 0 | AG14: =(kdis.w1S.w1D*M.w1RS+kdis.w1A.w1D*M.w1RA+kdis.w1P.w1D*M.w1RP)*Molweight -> 0 | AH14: =KDEG.w1R*VOLUME.w1R*C.w1R*Molweight -> 0 | AI14: =k.aRG.w1RD*M.aRG*Molweight -> 0 | AJ14: =k.w1RD.aRG*M.w1R*Molweight -> 0 | AM14: =(k.s1RD.w1RD*M.s1R+k.s2RD.w1RD*M.s2R+k.s3RD.w1RD*M.s3R)*Molweight -> 0 | AN14: =k.w1RD.sd1RD*M.w1R*Molweight -> 0 | AO14: =k.sd1RD.w1RD*M.sd1R*Molweight -> 0 | AP14: =SUM(AC14,AD14,AI14,AM14,AO14,AG14)-SUM(AF14,AE14,AH14,AJ14,AN14) -> 0 | AT14: Outflow | BX14: =IF(AL18<0,"",AL18) -> 0 | BZ14: =IF(AL20<0,"",AL20) -> 0 | CB14: =IF(AL19<0,"",AL19) -> 0
B15: Solid species (S) | C15: =(M.aRS+M.cwRS)*Molweight -> 9690.1971 | D15: =C15/$C$103 -> 5.856684e-07 | E15: =(M.aCS+M.cwCS)*Molweight -> 3498.113 | F15: =E15/$E$103 -> 1.0667582e-07 | G15: =(M.aMS+M.cwMS)*Molweight -> 185.48542 | H15: =G15/$G$103 -> 3.5859352e-11 | I15: =(M.aAS+M.cwAS)*Molweight -> 2.8894262 | J15: =I15/$I$103 -> 8.4517649e-13 | K15: =(M.aTS+M.cwTS)*Molweight -> 4.5154707 | L15: =K15/$K$103 -> 3.5329554e-13 | M15: =(M.aRS+M.cwRS)*(Molweight*1000)/(VOLUME.aR + VOLUME.cwR) -> 4.2210207e-08 | N15: =(M.aCS+M.cwCS)*(Molweight*1000)/(VOLUME.aC + VOLUME.cwC) -> 4.8589965e-10 | O15: =(M.aMS+M.cwMS)*(Molweight*1000)/(VOLUME.aM + VOLUME.cwM) -> 2.3911641e-12 | P15: =(M.aAS+M.cwAS)*(Molweight*1000)/(VOLUME.aA + VOLUME.cwA) -> 6.79865e-14 | Q15: =(M.aTS+M.cwTS)*(Molweight*1000)/(VOLUME.aT + VOLUME.cwT) -> 3.5415457e-14 | R15: g.m-3 | AA15: coastal sea water | AB15: w2R | AC15: =E.w2RD*Molweight -> 0 | AD15: =(k.w1R.w2R*M.w1R+k.w2C.w2R*M.w2C)*Molweight -> 0 | AE15: =k.w2R.w2C*M.w2R*Molweight -> 0 | AG15: =(kdis.w2S.w2D*M.w2RS+kdis.w2A.w2D*M.w2RA+kdis.w2P.w2D*M.w2RP)*Molweight -> 0 | AH15: =KDEG.w2R*M.w2RD*Molweight -> 0 | AI15: =k.aRG.w2RD*M.aRG*Molweight -> 0 | AJ15: =k.w2RD.aRG*M.w2R*Molweight -> 0 | AN15: =k.w2RD.sd2RD*M.w2R*Molweight -> 0 | AO15: =k.sd2RD.w2RD*M.sd2R*Molweight -> 0 | AP15: =SUM(AC15,AD15,AI15,AM15,AO15,AG15)-SUM(AF15,AE15,AH15,AJ15,AN15) -> 0 | AT15: Net export | BV15: =IF(AJ13<0,"",AJ13) -> 0
B16: Species attached to NCs (<450 nm) (A) | C16: =(M.aRA+M.cwRA)*Molweight -> 24606.827 | D16: =C16/$C$103 -> 1.4872186e-06 | E16: =(M.aCA+M.cwCA)*Molweight -> 121528.11 | F16: =E16/$E$103 -> 3.7060297e-06 | G16: =(M.aMA+M.cwMA)*Molweight -> 77402.38 | H16: =G16/$G$103 -> 1.4963975e-08 | I16: =(M.aAA+M.cwAA)*Molweight -> 15991.147 | J16: =I16/$I$103 -> 4.6775174e-09 | K16: =(M.aTA+M.cwTA)*Molweight -> 23830.918 | L16: =K16/$K$103 -> 1.864558e-09 | M16: =(M.aRA+M.cwRA)*(Molweight*1000)/(VOLUME.aR + VOLUME.cwR) -> 1.071866e-07 | N16: =(M.aCA+M.cwCA)*(Molweight*1000)/(VOLUME.aC + VOLUME.cwC) -> 1.6880663e-08 | O16: =(M.aMA+M.cwMA)*(Molweight*1000)/(VOLUME.aM + VOLUME.cwM) -> 9.9782393e-10 | P16: =(M.aAA+M.cwAA)*(Molweight*1000)/(VOLUME.aA + VOLUME.cwA) -> 3.7626228e-10 | Q16: =(M.aTA+M.cwTA)*(Molweight*1000)/(VOLUME.aT + VOLUME.cwT) -> 1.8690916e-10 | R16: g.m-3 | AA16: fresh water sediment | AB16: sd1R | AF16: =NETsedrate.w1R*SYSTEMAREA.R*AREAFRAC.w1R*C.sd1R*Molweight -> 0 | AG16: =(kdis.sd1S.sd1D*M.sd1RS+kdis.sd1A.sd1D*M.sd1RA+kdis.sd1P.sd1D*M.sd1RP)*Molweight -> 0 | AH16: =KDEG.sd1R*VOLUME.sd1R*C.sd1R*Molweight -> 0 | AN16: =k.w1RD.sd1RD*M.w1R*Molweight -> 0 | AO16: =k.sd1RD.w1RD*M.sd1R*Molweight -> 0 | AP16: =SUM(AC16,AD16,AN16,AG16)-SUM(AE16,AF16,AH16,AO16) -> 0 | BQ16: =IF(AJ15<0,"",AJ15) -> 0 | BT16: =IF(AJ14<0,"",AJ14) -> 0
B17: Species attached to suspended particles (>450 nm) (P) | C17: =(M.aRP+M.cwRP)*Molweight -> 9.8207059 | D17: =C17/$C$103 -> 5.9355625e-10 | E17: =(M.aCP+M.cwCP)*Molweight -> 5.1029017 | F17: =E17/$E$103 -> 1.5561424e-10 | G17: =(M.aMP+M.cwMP)*Molweight -> 0.2983313 | H17: =G17/$G$103 -> 5.7675513e-14 | I17: =(M.aAP+M.cwAP)*Molweight -> 0.01196339 | J17: =I17/$I$103 -> 3.4993714e-15 | K17: =(M.aTP+M.cwTP)*Molweight -> 0.0042889237 | L17: =K17/$K$103 -> 3.3557025e-16 | M17: =(M.aRP+M.cwRP)*(Molweight*1000)/(VOLUME.aR + VOLUME.cwR) -> 4.2778699e-11 | N17: =(M.aCP+M.cwCP)*(Molweight*1000)/(VOLUME.aC + VOLUME.cwC) -> 7.0881019e-13 | O17: =(M.aMP+M.cwMP)*(Molweight*1000)/(VOLUME.aM + VOLUME.cwM) -> 3.8459038e-15 | P17: =(M.aAP+M.cwAP)*(Molweight*1000)/(VOLUME.aA + VOLUME.cwA) -> 2.8149152e-16 | Q17: =(M.aTP+M.cwTP)*(Molweight*1000)/(VOLUME.aT + VOLUME.cwT) -> 3.3638617e-17 | R17: g.m-3 | AA17: coastal marine sediment | AB17: sd2R | AF17: =NETsedrate.w2R*SYSTEMAREA.R*AREAFRAC.w2R*C.sd2R*Molweight -> 0 | AG17: =(kdis.sd2S.sd2D*M.sd2RS+kdis.sd2A.sd2D*M.sd2RA+kdis.sd2P.sd2D*M.sd2RP)*Molweight -> 0 | AH17: =KDEG.sd2R*VOLUME.sd2R*C.sd2R*Molweight -> 0 | AN17: =k.w2RD.sd2RD*M.w2R*Molweight -> 0 | AO17: =k.sd2RD.w2RD*M.sd2R*Molweight -> 0 | AP17: =SUM(AC17,AD17,AN17,AG17)-SUM(AE17,AF17,AH17,AO17) -> 0 | AT17: Leaching | BV17: =IF(AK18<=0,ABS(AK18),"") -> 0 | BZ17: =IF(AK20<=0,ABS(AK20),"") -> 0 | CA17: =IF(AK19<=0,ABS(AK19),"") -> 0
AA18: natural soil | AB18: s1R | AC18: =E.s1RD*Molweight -> 0 | AF18: =(FRACinf.s1R*RAINrate.R/Ks1w.R*SYSTEMAREA.R*AREAFRAC.s1R*CORRleach.s1R)*C.s1R*Molweight -> 0 | AG18: =(kdis.s1S.s1D*M.s1RS+kdis.s1A.s1D*M.s1RA+kdis.s1P.s1D*M.s1RP)*Molweight -> 0 | AH18: =KDEG.s1R*VOLUME.s1R*C.s1R*Molweight -> 0 | AK18: =k.aRG.s1RD*M.aR*Molweight -> 0 | AL18: =k.s1RD.aRG*M.s1R*Molweight -> 0 | AM18: =k.s1RD.w1RD*M.s1R*Molweight -> 0 | AP18: =SUM(AC18,AD18,AK18,AG18)-SUM(AE18,AF18,AH18,AL18,AM18,AP17) -> 0 | AT18: Burial
B19: Fresh water lake | C19: =SUM(C20,C23:C25) -> 7748260.8 | D19: =C19/$C$103 -> 0.00046829919 | E19: =SUM(E20,E23:E25) -> 884035.62 | F19: =E19/$E$103 -> 2.6958884e-05 | M19: =(M.w0RD+M.w0RS+M.w0RA+M.w0RP)*Molweight/(VOLUME.w0R) -> 0.00013559541 | N19: =(M.w0CD+M.w0CS+M.w0CA+M.w0CP)*Molweight/(VOLUME.w0C) -> 1.0144305e-06 | R19: g.L-1 | AA19: agricultural soil | AB19: s2R | AC19: =E.s2RD*Molweight -> 0 | AF19: =(FRACinf.s2R*RAINrate.R/Ks2w.R*SYSTEMAREA.R*AREAFRAC.s2R*CORRleach.s2R)*C.s2R*Molweight -> 0 | AG19: =(kdis.s2S.s2D*M.s2RS+kdis.s2A.s2D*M.s2RA+kdis.s2P.s2D*M.s2RP)*Molweight -> 0 | AH19: =KDEG.s2R*VOLUME.s2R*C.s2R*Molweight -> 0 | AK19: =k.aRG.s2RD*M.aR*Molweight -> 0 | AL19: =k.s2RD.aRG*M.s2R*Molweight -> 0 | AM19: =k.s2RD.w1RD*M.s2R*Molweight -> 0 | AP19: =SUM(AC19,AD19,AK19,AG19)-SUM(AE19,AF19,AH19,AL19,AM19,AP18) -> 0 | AT19: Removal | BQ19: =IF(AI15<=0,ABS(AI15),"") -> 0 | BT19: =AM14 -> 0
B20: Dissolved/Gas species (G/D) | C20: =M.w0RD*Molweight -> 0 | D20: =C20/$C$103 -> 0 | E20: =M.w0CD*Molweight -> 0 | F20: =E20/$E$103 -> 0 | M20: =C.w0R*Molweight -> 0 | N20: =C.w0C*Molweight -> 0 | R20: g.L-1 | S20: =F.w0R -> 0 | T20: =F.w0C -> 0 | AA20: other soil | AB20: s3R | AC20: =E.s3RD*Molweight -> 0 | AF20: =(FRACinf.s3R*RAINrate.R/Ks3w.R*SYSTEMAREA.R*AREAFRAC.s3R*CORRleach.s3R)*C.s3R*Molweight -> 0 | AG20: =(kdis.s3S.s3D*M.s3RS+kdis.s3A.s3D*M.s3RA+kdis.s3P.s3D*M.s3RP)*Molweight -> 0 | AH20: =KDEG.s3R*VOLUME.s3R*C.s3R*Molweight -> 0 | AK20: =k.aRG.s3RD*M.aR*Molweight -> 0 | AL20: =k.s3RD.aRG*M.s3R*Molweight -> 0 | AM20: =k.s3RD.w1RD*M.s3R*Molweight -> 0 | AP20: =SUM(AC20,AD20,AK20,AG20)-SUM(AE20,AF20,AH20,AL20,AM20,AP19) -> 0 | AT20: Degradation | BQ20: =IF(AI15<0,"",AI15) -> 0 | BT20: =IF(AI14<0,"",AI14) -> 0 | BV20: =IF(AI13<0,"",AI13) -> 0 | BX20: =IF(AK18<0,"",AK18) -> 0 | BZ20: =IF(AK20<0,"",AK20) -> 0 | CB20: =IF(AK19<0,"",AK19) -> 0
B21: * DISSOLVED | C21: =FRwD.w0R*C20 -> 0 | D21: =C21/$C$103 -> 0 | E21: =FRw.w0C*E20 -> 0 | F21: =E21/$E$103 -> 0 | M21: =M20*FRwD.w0R -> 0 | N21: =N20*FRw.w0C -> 0 | R21: g.L-1 | S21: =S20*FRwD.w0R -> 0 | T21: =T20*FRw.w0C -> 0 | AA21: Continetal Scale | BN21: =AE13 -> 0
B22: * SUSPENDED SOLIDS | C22: =(1-FRwD.w0R)*C20 -> 0 | D22: =C22/$C$103 -> 0 | E22: =(1-FRw.w0C)*E20 -> 0 | F22: =E22/$E$103 -> 0 | M22: =M21*Kp.susp1R -> 0 | N22: =N21*Kp.susp1C -> 0 | R22: g.kg(d)-1 | S22: =S20*(1-FRwD.w0R) -> 0 | T22: =T20*(1-FRw.w0C) -> 0 | AA22: air | AB22: aC | AC22: =E.aCG*Molweight -> 0 | AD22: =(k.aR.aC*M.aR+k.aM.aC*M.aM)*Molweight -> 0 | AE22: =(k.aC.aM+k.aC.aR)*M.aC*Molweight -> 0 | AF22: =kesc.aC*VOLUME.aC*C.aC*Molweight -> 0 | AH22: =KDEG.aC*VOLUME.aC*C.aC*Molweight -> 0 | AI22: =SUM(AI23:AI25,AK28:AK30) -> 0 | AJ22: =SUM(AJ23:AJ25,AL28:AL30) -> 0 | AP22: =SUM(AC22,AD22,AJ22,AL22)-SUM(AE22,AF22,AH22,AI22,AK22) -> 0 | AT22: Wet and dry deposition | BN22: =AE14 -> 0 | BS22: =AD14 -> 0
B23: Solid species (S) | C23: =M.w0RS*Molweight -> 0.67907339 | D23: =C23/$C$103 -> 4.1042697e-11 | E23: =M.w0CS*Molweight -> 0.119125 | F23: =E23/$E$103 -> 3.6327463e-12 | M23: =C.w0RS*Molweight -> 1.1883859e-11 | N23: =C.w0CS*Molweight -> 1.3669589e-13 | R23: g.L-1 | AA23: fresh water lakes | AB23: w0C | AC23: =E.w0CD*Molweight -> 0 | AD23: =k.w1C.w0C*M.w1C*Molweight -> 0 | AE23: =(k.w0C.w1C+k.w0C.w2C)*M.w0C*Molweight -> 0 | AG23: =(kdis.w0S.w0D*M.w0CS+kdis.w0A.w0D*M.w0CA+kdis.w0P.w0D*M.w0CP)*Molweight -> 0 | AH23: =KDEG.w0C*VOLUME.w0C*C.w0C*Molweight -> 0 | AI23: =k.aC.w0C*M.aC*Molweight -> 0 | AJ23: =k.w0C.aC*M.w0C*Molweight -> 0 | AN23: =k.w0C.sd0C*M.w0CD*Molweight -> 0 | AO23: =k.sd0C.w0C*M.sd0CD*Molweight -> 0 | AP23: =SUM(AC23,AD23,AI23,AM23,AO23,AG23)-SUM(AF23,AE23,AH23,AJ23,AN23) -> 0 | AT23: Net gas absorption | BN23: =AE15 -> 0 | BP23: =AD15 -> 0 | BT23: =AH14 -> 0 | BV23: =AH13 -> 0
B24: Species attached to NCs (<450 nm) (A) | C24: =M.w0RA*Molweight -> 7725840.9 | D24: =C24/$C$103 -> 0.00046694415 | E24: =M.w0CA*Molweight -> 883788.83 | F24: =E24/$E$103 -> 2.6951358e-05 | M24: =C.w0RA*Molweight -> 0.00013520306 | N24: =C.w0CA*Molweight -> 1.0141473e-06 | R24: g.L-1 | AA24: fresh water | AB24: w1C | AC24: =E.w1CD*Molweight -> 0 | AD24: =k.w0C.w1C*M.w0C*Molweight -> 0 | AE24: =(k.w1C.w0C+k.w1C.w1R+k.w1C.w2C)*M.w1C*Molweight -> 0 | AG24: =(kdis.w1S.w1D*M.w1CS+kdis.w1A.w1D*M.w1CA+kdis.w1P.w1D*M.w1CP)*Molweight -> 0 | AH24: =KDEG.w1C*VOLUME.w1C*C.w1C*Molweight -> 0 | AI24: =k.aC.w1C*M.aC*Molweight -> 0 | AJ24: =k.w1C.aC*M.w1C*Molweight -> 0 | AM24: =(k.s1C.w1C*M.s1C+k.s2C.w1C*M.s2C+k.s3C.w1C*M.s3C)*Molweight -> 0 | AN24: =k.w1C.sd1C*M.w1C*Molweight -> 0 | AO24: =k.sd1C.w1C*M.sd1C*Molweight -> 0 | AP24: =SUM(AC24,AD24,AI24,AM24,AO24,AG24)-SUM(AF24,AE24,AH24,AJ24,AN24) -> 0 | BV24: =AC13 -> 0
B25: Species attached to suspended particles (>450 nm) (P) | C25: =M.w0RP*Molweight -> 22419.216 | D25: =C25/$C$103 -> 1.3550009e-06 | E25: =M.w0CP*Molweight -> 246.66256 | F25: =E25/$E$103 -> 7.5220355e-09 | M25: =C.w0RP*Molweight -> 3.9233873e-07 | N25: =C.w0CP*Molweight -> 2.8304519e-10 | R25: g.L-1 | AA25: coastal sea water | AB25: w2C | AC25: =E.w2CD*Molweight -> 0 | AD25: =(k.w2M.w2C*M.w2M+k.w2R.w2C*M.w2R+k.w1C.w2C*M.w1C)*Molweight -> 0 | AE25: =(k.w2C.w2M+k.w2C.w2R)*M.w2C*Molweight -> 0 | AG25: =(kdis.w2S.w2D*M.w2CS+kdis.w2A.w2D*M.w2CA+kdis.w2P.w2D*M.w2CP)*Molweight -> 0 | AH25: =KDEG.w2C*VOLUME.w2C*C.w2C*Molweight -> 0 | AI25: =k.aC.w2C*M.aC*Molweight -> 0 | AJ25: =k.w2C.aC*M.w2C*Molweight -> 0 | AN25: =k.w2C.sd2C*M.w2C*Molweight -> 0 | AO25: =k.sd2C.w2C*M.sd2C*Molweight -> 0 | AP25: =SUM(AC25,AD25,AI25,AM25,AO25,AG25)-SUM(AF25,AE25,AH25,AJ25,AN25) -> 0 | AT25: Run off | BS25: =AC14 -> 0 | BT25: Fresh water: | BV25: Fresh water lake:
AA26: fresh water sediment | AB26: sd1C | AF26: =(NETsedrate.w1C*SYSTEMAREA.C*AREAFRAC.w1C)*C.sd1C*Molweight -> 0 | AG26: =(kdis.sd1S.sd1D*M.sd1CS+kdis.sd1A.sd1D*M.sd1CA+kdis.sd1P.sd1D*M.sd1CP)*Molweight -> 0 | AH26: =KDEG.sd1C*VOLUME.sd1C*C.sd1C*Molweight -> 0 | AN26: =k.w1C.sd1C*M.w1C*Molweight -> 0 | AO26: =k.sd1C.w1C*M.sd1C*Molweight -> 0 | AP26: =SUM(AC26,AD26,AN26,AG26)-SUM(AE26,AF26,AH26,AO26) -> 0 | BP26: =AC15 -> 0 | BS26: =IF(AO16<0,"",AO16) -> 0 | BT26: =IF(ISERROR(D36),0,D36) -> 0 | BV26: =IF(ISERROR(F36),0,D20) -> 0 | BX26: Natural soil: | BZ26: Other soil: | CC26: Agricultural soil:
B27: Fresh water lake sediment | C27: =SUM(C28,C31:C33) -> 3587232.1 | D27: =C27/$C$103 -> 0.00021680967 | E27: =SUM(E28,E31:E33) -> 176191.42 | F27: =E27/$E$103 -> 5.3730007e-06 | M27: =((M.sd0RD+M.sd0RS+M.sd0RA+M.sd0RP)*Molweight*1000/(VOLUME.sd0R))/(FRACw.sdR*1000+FRACs.sdR*RHOsolid) -> 0.16096655 | N27: =((M.sd0CD+M.sd0CS+M.sd0CA+M.sd0CP)*Molweight*1000/(VOLUME.sd0C))/(FRACw.sdC*1000+FRACs.sdC*RHOsolid) -> 0.00051840918 | R27: g.kg(w)-1 | AA27: coastal marine sediment | AB27: sd2C | AF27: =(NETsedrate.w2C*SYSTEMAREA.C*AREAFRAC.w2C)*C.sd2C*Molweight -> 0 | AG27: =(kdis.sd2S.sd2D*M.sd2CS+kdis.sd2A.sd2D*M.sd2CA+kdis.sd2P.sd2D*M.sd2CP)*Molweight -> 0 | AH27: =KDEG.sd2C*VOLUME.sd2C*C.sd2C*Molweight -> 0 | AN27: =k.w2C.sd2C*M.w2C*Molweight -> 0 | AO27: =k.sd2C.w2C*M.sd2C*Molweight -> 0 | AP27: =SUM(AC27,AD27,AN27,AG27)-SUM(AE27,AF27,AH27,AO27) -> 0 | AT27: Sedimentation | BX27: =IF(ISERROR(D76),0,D76) -> 0 | BZ27: =IF(ISERROR(D92),0,D92) -> 0 | CC27: =IF(ISERROR(D84),0,D84) -> 0
B28: Dissolved/Gas species (G/D) | C28: =M.sd0RD*Molweight -> 0 | D28: =C28/$C$103 -> 0 | E28: =M.sd0CD*Molweight -> 0 | F28: =E28/$E$103 -> 0 | M28: =C.sd0RD*(Molweight*1000)/(FRACw.sdR*1000+FRACs.sdR*RHOsolid) -> 0 | N28: =C.sd0CD*(Molweight*1000)/(FRACw.sdC*1000+FRACs.sdC*RHOsolid) -> 0 | R28: g.kg(w)-1 | AA28: natural soil | AB28: s1C | AC28: =E.s1CD*Molweight -> 0 | AF28: =(FRACinf.s1C*RAINrate.C/Ks1w.C*SYSTEMAREA.C*AREAFRAC.s1C*CORRleach.s1C)*C.s1C*Molweight -> 0 | AG28: =(kdis.s1S.s1D*M.s1CS+kdis.s1A.s1D*M.s1CA+kdis.s1P.s1D*M.s1CP)*Molweight -> 0 | AH28: =KDEG.s1C*VOLUME.s1C*C.s1C*Molweight -> 0 | AK28: =k.aC.s1C*M.aC*Molweight -> 0 | AL28: =k.s1C.aC*M.s1C*Molweight -> 0 | AM28: =k.s1C.w1C*M.s1C*Molweight -> 0 | AP28: =SUM(AC28,AD28,AK28,AG28)-SUM(AE28,AF28,AH28,AL28,AM28,AP27) -> 0 | AT28: Adsorption | BS28: =IF(AN16<0,"",AN16) -> 0 | BT28: =AH16 -> 0
B29: * PORE WATER | C29: =C28*FRACw.sdR -> 0 | D29: =C29/$C$103 -> 0 | E29: =E28*FRACw.sdC -> 0 | F29: =E29/$E$103 -> 0 | M29: =M30/Kp.sd0R -> 0 | N29: =N30/Kp.sd0C -> 0 | R29: g.L-1 | AA29: agricultural soil | AB29: s2C | AC29: =E.s2CD*Molweight -> 0 | AF29: =(FRACinf.s2C*RAINrate.C/Ks2w.C*SYSTEMAREA.C*AREAFRAC.s2C*CORRleach.s2C)*C.s2C*Molweight -> 0 | AG29: =(kdis.s2S.s2D*M.s2CS+kdis.s2A.s2D*M.s2CA+kdis.s2P.s2D*M.s2CP)*Molweight -> 0 | AH29: =KDEG.s2C*VOLUME.s2C*C.s2C*Molweight -> 0 | AK29: =k.aC.s2C*M.aC*Molweight -> 0 | AL29: =k.s2C.aC*M.s2C*Molweight -> 0 | AM29: =k.s2C.w1C*M.s2C*Molweight -> 0 | AP29: =SUM(AC29,AD29,AK29,AG29)-SUM(AE29,AF29,AH29,AL29,AM29,AP28) -> 0 | BX29: =AH18 -> 0 | BZ29: =AH20 -> 0 | CC29: =AH19 -> 0
B30: * SOLID PHASE | C30: =C28*FRACs.sdR -> 0 | D30: =C30/$C$103 -> 0 | E30: =E28*FRACs.sdC -> 0 | F30: =E30/$E$103 -> 0 | M30: =C.sd0RD*FRACs.sdR/(FRACw.sdR/(Kp.sd0R*RHOsolid/1000)+FRACs.sdR)*(Molweight*1000*1000)/(FRACs.sdR*RHOsolid) -> 0 | N30: =C.sd0CD*FRACs.sdC/(FRACw.sdC/(Kp.sd0C*RHOsolid/1000)+FRACs.sdC)*(Molweight*1000*1000)/(FRACs.sdC*RHOsolid) -> 0 | R30: g.kg(d)-1 | AA30: other soil | AB30: s3C | AC30: =E.s3CD*Molweight -> 0 | AF30: =(FRACinf.s3C*RAINrate.C/Ks3w.C*SYSTEMAREA.C*AREAFRAC.s3C*CORRleach.s3C)*C.s3C*Molweight -> 0 | AG30: =(kdis.s3S.s3D*M.s3CS+kdis.s3A.s3D*M.s3CA+kdis.s3P.s3D*M.s3CP)*Molweight -> 0 | AH30: =KDEG.s3C*VOLUME.s3C*C.s3C*Molweight -> 0 | AK30: =k.aC.s3C*M.aC*Molweight -> 0 | AL30: =k.s3C.aC*M.s3C*Molweight -> 0 | AM30: =k.s3C.w1C*M.s3C*Molweight -> 0 | AP30: =SUM(AC30,AD30,AK30,AG30)-SUM(AE30,AF30,AH30,AL30,AM30,AP29) -> 0 | AT30: plant death & litter fall | BS30: Fresh water sediment:
B31: Solid species (S) | C31: =M.sd0RS*Molweight -> 8.8227862e-09 | D31: =C31/$C$103 -> 5.3324272e-19 | E31: =M.sd0CS*Molweight -> 5.6603914e-10 | F31: =E31/$E$103 -> 1.7261503e-20 | M31: =C.sd0RS*(Molweight*1000)/(FRACw.sdR*1000+FRACs.sdR*RHOsolid) -> 3.9589673e-16 | N31: =C.sd0CS*(Molweight*1000)/(FRACw.sdC*1000+FRACs.sdC*RHOsolid) -> 1.6654607e-18 | R31: g.kg(w)-1 | AA31: Global Scale - Moderate climate zone | AT31: transpiration flux | BT31: =IF(ISERROR(D44),0,D44) -> 0
B32: Species attached to NCs (<450 nm) (A) | C32: =M.sd0RA*Molweight -> 1309944.6 | D32: =C32/$C$103 -> 7.9172092e-05 | E32: =M.sd0CA*Molweight -> 150951.78 | F32: =E32/$E$103 -> 4.6033115e-06 | M32: =C.sd0RA*(Molweight*1000)/(FRACw.sdR*1000+FRACs.sdR*RHOsolid) -> 0.058779934 | N32: =C.sd0CA*(Molweight*1000)/(FRACw.sdC*1000+FRACs.sdC*RHOsolid) -> 0.00044414641 | R32: g.kg(w)-1 | AA32: air | AB32: aM | AC32: =E.aMG*Molweight -> 0 | AD32: =(k.aC.aM*M.aC+k.aA.aM*M.aA+k.aT.aM*M.aT)*Molweight -> 0 | AE32: =(k.aM.aA+k.aM.aC+k.aM.aT)*M.aM*Molweight -> 0 | AF32: =kesc.aM*VOLUME.aM*C.aM*Molweight -> 0 | AH32: =KDEG.aM*VOLUME.aM*C.aM*Molweight -> 0 | AI32: =SUM(AI33,AK36) -> 0 | AJ32: =SUM(AJ33,AL36) -> 0 | AP32: =SUM(AC32,AD32,AJ32,AL32)-SUM(AE32,AF32,AH32,AI32,AK32) -> 0 | AT32: Balance | BQ32: =AH15 -> 0
B33: Species attached to suspended particles (>450 nm) (P) | C33: =M.sd0RP*Molweight -> 2277287.5 | D33: =C33/$C$103 -> 0.00013763758 | E33: =M.sd0CP*Molweight -> 25239.643 | F33: =E33/$E$103 -> 7.6968913e-07 | M33: =C.sd0RP*(Molweight*1000)/(FRACw.sdR*1000+FRACs.sdR*RHOsolid) -> 0.10218661 | N33: =C.sd0CP*(Molweight*1000)/(FRACw.sdC*1000+FRACs.sdC*RHOsolid) -> 7.426277e-05 | R33: g.kg(w)-1 | AA33: upper ocean water | AB33: w2M | AC33: =E.w2MD*Molweight -> 0 | AD33: =(k.w2C.w2M*M.w2C+k.w2A.w2M*M.w2A+k.w2T.w2M*M.w2T+k.w3M.w2M*M.w3M)*Molweight -> 0 | AE33: =(k.w2M.w2C+k.w2M.w2A+k.w2M.w2T+k.w2M.w3M)*M.w2M*Molweight -> 0 | AG33: =(kdis.w2S.w2D*M.w2MS+kdis.w2A.w2D*M.w2MA+kdis.w2P.w2D*M.w2MP)*Molweight -> 0 | AH33: =KDEG.w2M*VOLUME.w2M*C.w2M*Molweight -> 0 | AI33: =k.aM.w2M*M.aM*Molweight -> 0 | AJ33: =k.w2M.aM*M.w2M*Molweight -> 0 | AM33: =k.sM.w2M*M.sM*Molweight -> 0 | AP33: =SUM(AC33,AD33,AI33,AM33,AG33)-SUM(AE33,AF33,AH33,AJ33) -> 0 | BQ33: Seawater:
AA34: deep sea | AB34: w3M | AD34: =(k.w2M.w3M*M.w2M+k.w3A.w3M*M.w3A+k.w3T.w3M*M.w3T)*Molweight -> 0 | AE34: =(k.w3M.w2M+k.w3M.w3A+k.w3M.w3T)*M.w3M*Molweight -> 0 | AG34: =(kdis.w2S.w2D*M.w3MS+kdis.w2A.w2D*M.w3MA+kdis.w2P.w2D*M.w3MP)*Molweight -> 0 | AH34: =KDEG.w3M*M.w3MD*Molweight -> 0 | AN34: =k.w3M.sdM*M.w3M*Molweight -> 0 | AO34: =k.sdM.w3M*M.sdM*Molweight -> 0 | AP34: =SUM(AC34,AD34,AI34,AM34,AO34,AG34)-SUM(AE34,AF34,AH34,AJ34,AN34) -> 0 | AU34: aM | AV34: w2M | AW34: w3M | AX34: sdM | AY34: sM | AZ34: aA | BA34: w2A | BB34: w3A | BC34: sdA | BD34: sA | BE34: aT | BF34: w2T | BG34: w3T | BH34: sdT | BI34: sT | BJ34: Sum | BP34: =IF(AO17<0,"",AO17) -> 0 | BQ34: =IF(ISERROR(D52),0,D52) -> 0
B35: Fresh water | C35: =SUM(C36,C39:C41) -> 7304629.4 | D35: =C35/$C$103 -> 0.00044148644 | E35: =SUM(E36,E39:E41) -> 406969.14 | F35: =E35/$E$103 -> 1.2410624e-05 | M35: =(M.w1RD+M.w1RS+M.w1RA+M.w1RP)*Molweight/(VOLUME.w1R) -> 0.00038736913 | N35: =(M.w1CD+M.w1CS+M.w1CA+M.w1CP)*Molweight/(VOLUME.w1C) -> 1.4151422e-06 | R35: g.L-1 | AA35: ocean sediment | AB35: sdM | AF35: =(NETsedrate.wM*SYSTEMAREA.M*AREAFRAC.wM)*C.sdM*Molweight -> 0 | AG35: =(kdis.sd2S.sd2D*M.sdMS+kdis.sd2A.sd2D*M.sdMA+kdis.sd2P.sd2D*M.sdMP)*Molweight -> 0 | AH35: =KDEG.sdM*M.sdMD*Molweight -> 0 | AN35: =k.w3M.sdM*M.w3M*Molweight -> 0 | AO35: =k.sdM.w3M*M.sdM*Molweight -> 0 | AP35: =SUM(AC35,AD35,AN35,AG35)-SUM(AE35,AF35,AH35,AO35) -> 0 | CB35: =AC19 -> 0
B36: Dissolved/Gas species (G/D) | C36: =M.w1RD*Molweight -> 0 | D36: =C36/$C$103 -> 0 | E36: =M.w1CD*Molweight -> 0 | F36: =E36/$E$103 -> 0 | M36: =C.w1R*Molweight -> 0 | N36: =C.w1C*Molweight -> 0 | R36: g.L-1 | S36: =F.w1R -> 0 | T36: =F.w1C -> 0 | AA36: soil | AB36: sM | AC36: =E.sMD*Molweight -> 0 | AF36: =(FRACinf.sM*RAINrate.M/Kslw.M*SYSTEMAREA.M*AREAFRAC.sM*CORRleach.sM)*C.sM*Molweight -> 0 | AG36: =(kdis.s1S.s1D*M.sMS+kdis.s1A.s1D*M.sMA+kdis.s1P.s1D*M.sMP)*Molweight -> 0 | AH36: =KDEG.sM*VOLUME.sM*C.sM*Molweight -> 0 | AK36: =k.aM.sM*M.aM*Molweight -> 0 | AL36: =k.sM.aM*M.sM*Molweight -> 0 | AM36: =k.sM.w2M*M.sM*Molweight -> 0 | AP36: =SUM(AC36,AD36,AK36,AG36)-SUM(AE36,AF36,AH36,AL36,AM36,AP35) -> 0 | AT36: Emission | BZ36: =AC20 -> 0
B37: * DISSOLVED | C37: =FRwD.w1R*C36 -> 0 | D37: =C37/$C$103 -> 0 | E37: =FRw.w1C*E36 -> 0 | F37: =E37/$E$103 -> 0 | M37: =M36*FRwD.w1R -> 0 | N37: =N36*FRw.w1C -> 0 | R37: g.L-1 | S37: =S36*FRwD.w1R -> 0 | T37: =T36*FRw.w1C -> 0 | AA37: Global Scale - Arctic climate zone | BP37: =IF(AN17<0,"",AN17) -> 0 | BQ37: =AH17 -> 0 | BV37: =AC18 -> 0
B38: * SUSPENDED SOLIDS | C38: =(1-FRwD.w1R)*C36 -> 0 | D38: =C38/$C$103 -> 0 | E38: =(1-FRw.w1C)*E36 -> 0 | F38: =E38/$E$103 -> 0 | M38: =M37*Kp.susp1R -> 0 | N38: =N37*Kp.susp1C -> 0 | R38: g.kg(d)-1 | S38: =S36*(1-FRwD.w1R) -> 0 | T38: =T36*(1-FRw.w1C) -> 0 | AA38: air | AB38: aA | AC38: =E.aAG*Molweight -> 0 | AD38: =k.aM.aA*M.aM*Molweight -> 0 | AE38: =k.aA.aM*M.aA*Molweight -> 0 | AF38: =kesc.aA*VOLUME.aA*C.aA*Molweight -> 0 | AH38: =KDEG.aA*VOLUME.aA*C.aA*Molweight -> 0 | AI38: =SUM(AI39,AK42) -> 0 | AJ38: =SUM(AJ39,AL42) -> 0 | AP38: =SUM(AC38,AD38,AJ38,AL38)-SUM(AE38,AF38,AH38,AI38,AK38) -> 0 | AT38: Inflow | BP38: Sea water sediment:
B39: Solid species (S) | C39: =M.w1RS*Molweight -> 1693.2651 | D39: =C39/$C$103 -> 1.023397e-07 | E39: =M.w1CS*Molweight -> 1.1039298 | F39: =E39/$E$103 -> 3.366461e-11 | M39: =C.w1RS*Molweight -> 8.9794924e-08 | N39: =C.w1CS*Molweight -> 3.8386635e-12 | R39: g.L-1 | AA39: upper ocean water | AB39: w2A | AC39: =E.w2AD*Molweight -> 0 | AD39: =(k.w2M.w2A*M.w2M+k.w3A.w2A*M.w3A)*Molweight -> 0 | AE39: =(k.w2A.w2M+k.w2A.w3A)*M.w2A*Molweight -> 0 | AG39: =(kdis.w2S.w2D*M.w2AS+kdis.w2A.w2D*M.w2AA+kdis.w2P.w2D*M.w2AP)*Molweight -> 0 | AH39: =KDEG.w2A*VOLUME.w2A*C.w2A*Molweight -> 0 | AI39: =k.aA.w2A*M.aA*Molweight -> 0 | AJ39: =k.w2A.aA*M.w2A*Molweight -> 0 | AM39: =k.sA.w2A*M.sA*Molweight -> 0 | AP39: =SUM(AC39,AD39,AI39,AM39,AG39)-SUM(AE39,AF39,AH39,AJ39) -> 0 | AT39: Outflow | BQ39: =IF(ISERROR(D68),0,D68) -> 0
B40: Species attached to NCs (<450 nm) (A) | C40: =M.w1RA*Molweight -> 7186862.1 | D40: =C40/$C$103 -> 0.00043436867 | E40: =M.w1CA*Molweight -> 406169.6 | F40: =E40/$E$103 -> 1.2386242e-05 | M40: =C.w1RA*Molweight -> 0.00038112386 | N40: =C.w1CA*Molweight -> 1.412362e-06 | R40: g.L-1 | AA40: deep sea | AB40: w3A | AD40: =(k.w2A.w3A*M.w2A+k.w3M.w3A*M.w3M)*Molweight -> 0 | AE40: =(k.w3A.w2A+k.w3A.w3M)*M.w3A*Molweight -> 0 | AG40: =(kdis.w2S.w2D*M.w3AS+kdis.w2A.w2D*M.w3AA+kdis.w2P.w2D*M.w3AP)*Molweight -> 0 | AH40: =KDEG.w3A*VOLUME.w3A*C.w3A*Molweight -> 0 | AN40: =k.w3A.sdA*M.w3A*Molweight -> 0 | AO40: =k.sdA.w3A*M.sdA*Molweight -> 0 | AP40: =SUM(AC40,AD40,AI40,AM40,AO40,AG40)-SUM(AE40,AF40,AH40,AJ40,AN40) -> 0 | AT40: Net export
B41: Species attached to suspended particles (>450 nm) (P) | C41: =M.w1RP*Molweight -> 116074.05 | D41: =C41/$C$103 -> 7.0154301e-06 | E41: =M.w1CP*Molweight -> 798.43565 | F41: =E41/$E$103 -> 2.4348492e-08 | M41: =C.w1RP*Molweight -> 6.1554803e-06 | N41: =C.w1CP*Molweight -> 2.7763775e-09 | R41: g.L-1 | AA41: ocean sediment | AB41: sdA | AF41: =(NETsedrate.wA*SYSTEMAREA.A*AREAFRAC.wA)*C.sdA*Molweight -> 0 | AG41: =(kdis.sd2S.sd2D*M.sdAS+kdis.sd2A.sd2D*M.sdAA+kdis.sd2P.sd2D*M.sdAP)*Molweight -> 0 | AH41: =KDEG.sdA*VOLUME.sdA*C.sdA*Molweight -> 0 | AN41: =k.w3A.sdA*M.w3A*Molweight -> 0 | AO41: =k.sdA.w3A*M.sdA*Molweight -> 0 | AP41: =SUM(AC41,AD41,AN41,AG41)-SUM(AE41,AF41,AH41,AO41) -> 0
AA42: soil | AB42: sA | AC42: =E.sAD*Molweight -> 0 | AF42: =(FRACinf.sA*RAINrate.A/Kslw.A*SYSTEMAREA.A*AREAFRAC.sA*CORRleach.sA)*C.sA*Molweight -> 0 | AG42: =(kdis.s1S.s1D*M.sAS+kdis.s1A.s1D*M.sAA+kdis.s1P.s1D*M.sAP)*Molweight -> 0 | AH42: =KDEG.sA*VOLUME.sA*C.sA*Molweight -> 0 | AK42: =k.aA.sA*M.aA*Molweight -> 0 | AL42: =k.sA.aA*M.sA*Molweight -> 0 | AM42: =k.sA.w2A*M.sA*Molweight -> 0 | AP42: =SUM(AC42,AD42,AK42,AG42)-SUM(AE42,AF42,AH42,AL42,AM42,AP41) -> 0 | AT42: Leaching
...

Sheet nano micro output
A2: Concentration ENPs (S+A+P) | I2: Species Concentration free ENPs (S) | Q2: Relevant bioavailable concentration according to user
B3: Regional | C3: Continental | D3: Moderate | E3: Arctic | F3: Tropical | J3: Regional | K3: Continental | L3: Moderate | M3: Arctic | N3: Tropical | Q3: User defined cut-off diameter | R3: 450 | S3: nm
A4: Air | B4: =J4+J18+J32 -> 1.4943958e-07 | C4: =K4+K18+K32 -> 1.7367271e-08 | D4: =L4+L18+L32 -> 1.0002189e-09 | E4: =M4+M18+M32 -> 3.7633055e-10 | F4: =N4+N18+N32 -> 1.8694461e-10 | G4: g.m-3 | I4: Air | J4: ='all species output'!$M15 -> 4.2210207e-08 | K4: ='all species output'!$N15 -> 4.8589965e-10 | L4: ='all species output'!$O15 -> 2.3911641e-12 | M4: ='all species output'!$P15 -> 6.79865e-14 | N4: ='all species output'!$Q15 -> 3.5415457e-14 | O4: g.m-3 | R4: Regional | S4: Continental | T4: Moderate | U4: Arctic | V4: Tropical
A5: Fresh water lake | B5: =J5+J19+J33 -> 0.00013559541 | C5: =K5+K19+K33 -> 1.0144305e-06 | G5: g.L-1 | I5: Fresh water lake | J5: ='all species output'!$M23 -> 1.1883859e-11 | K5: ='all species output'!$N23 -> 1.3669589e-13 | O5: g.L-1 | Q5: Air | R5: =IF((RadP.a*2)<bioavai.cutoff.diameter*0.000000001,'nano micro output'!B4,IF((RadA.w*2)<bioavai.cutoff.diameter*0.000000001,'nano micro output'!J4+'nano micro output'!J18,IF((RadS*2)<bioavai.cutoff.diameter*0.000000001,'nano micro output'!J4,0))) -> 1.493968e-07 | S5: =IF((RadP.a*2)<bioavai.cutoff.diameter*0.000000001,'nano micro output'!C4,IF((RadA.w*2)<bioavai.cutoff.diameter*0.000000001,'nano micro output'!K4+'nano micro output'!K18,IF((RadS*2)<bioavai.cutoff.diameter*0.000000001,'nano micro output'!K4,0))) -> 1.7366563e-08 | T5: =IF((RadP.a*2)<bioavai.cutoff.diameter*0.000000001,'nano micro output'!D4,IF((RadA.w*2)<bioavai.cutoff.diameter*0.000000001,'nano micro output'!L4+'nano micro output'!L18,IF((RadS*2)<bioavai.cutoff.diameter*0.000000001,'nano micro output'!L4,0))) -> 1.0002151e-09 | U5: =IF((RadP.a*2)<bioavai.cutoff.diameter*0.000000001,'nano micro output'!E4,IF((RadA.w*2)<bioavai.cutoff.diameter*0.000000001,'nano micro output'!M4+'nano micro output'!M18,IF((RadS*2)<bioavai.cutoff.diameter*0.000000001,'nano micro output'!M4,0))) -> 3.7633027e-10 | V5: =IF((RadP.a*2)<bioavai.cutoff.diameter*0.000000001,'nano micro output'!F4,IF((RadA.w*2)<bioavai.cutoff.diameter*0.000000001,'nano micro output'!N4+'nano micro output'!N18,IF((RadS*2)<bioavai.cutoff.diameter*0.000000001,'nano micro output'!N4,0))) -> 1.8694457e-10 | W5: g.m-3
A6: Fresh water lake sediment | B6: =J6+J20+J34 -> 0.16096655 | C6: =K6+K20+K34 -> 0.00051840918 | G6: g.kg(w)-1 | I6: Fresh water lake sediment | J6: ='all species output'!$M31 -> 3.9589673e-16 | K6: ='all species output'!$N31 -> 1.6654607e-18 | O6: g.kg(w)-1 | Q6: Fresh water lake | R6: =IF((RadP.w*2)<bioavai.cutoff.diameter*0.000000001,'nano micro output'!B5,IF((RadA.w*2)<bioavai.cutoff.diameter*0.000000001,'nano micro output'!J5+'nano micro output'!J19,IF((RadS*2)<bioavai.cutoff.diameter*0.000000001,'nano micro output'!J5,0))) -> 0.00013520307 | S6: =IF((RadP.w*2)<bioavai.cutoff.diameter*0.000000001,'nano micro output'!C5,IF((RadA.w*2)<bioavai.cutoff.diameter*0.000000001,'nano micro output'!K5+'nano micro output'!K19,IF((RadS*2)<bioavai.cutoff.diameter*0.000000001,'nano micro output'!K5,0))) -> 1.0141475e-06 | W6: g.L-1
A7: Fresh water | B7: =J7+J21+J35 -> 0.00038736913 | C7: =K7+K21+K35 -> 1.4151422e-06 | G7: g.L-1 | I7: Fresh water | J7: ='all species output'!$M39 -> 8.9794924e-08 | K7: ='all species output'!$N39 -> 3.8386635e-12 | O7: g.L-1 | Q7: Fresh water lake sediment | R7: =IF((RadP.w*2)<bioavai.cutoff.diameter*0.000000001,'nano micro output'!B6,IF((RadA.w*2)<bioavai.cutoff.diameter*0.000000001,'nano micro output'!J6+'nano micro output'!J20,IF((RadS*2)<bioavai.cutoff.diameter*0.000000001,'nano micro output'!J6,0))) -> 0.058779934 | S7: =IF((RadP.w*2)<bioavai.cutoff.diameter*0.000000001,'nano micro output'!C6,IF((RadA.w*2)<bioavai.cutoff.diameter*0.000000001,'nano micro output'!K6+'nano micro output'!K20,IF((RadS*2)<bioavai.cutoff.diameter*0.000000001,'nano micro output'!K6,0))) -> 0.00044414641 | W7: g.kg(w)-1
A8: Fresh water sediment | B8: =J8+J22+J36 -> 0.17414505 | C8: =K8+K22+K36 -> 0.0001338005 | G8: g.kg(w)-1 | I8: Fresh water sediment | J8: ='all species output'!$M47 -> 2.9912654e-12 | K8: ='all species output'!$N47 -> 4.6768273e-17 | O8: g.kg(w)-1 | Q8: Fresh water | R8: =IF((RadP.w*2)<bioavai.cutoff.diameter*0.000000001,'nano micro output'!B7,IF((RadA.w*2)<bioavai.cutoff.diameter*0.000000001,'nano micro output'!J7+'nano micro output'!J21,IF((RadS*2)<bioavai.cutoff.diameter*0.000000001,'nano micro output'!J7,0))) -> 0.00038121365 | S8: =IF((RadP.w*2)<bioavai.cutoff.diameter*0.000000001,'nano micro output'!C7,IF((RadA.w*2)<bioavai.cutoff.diameter*0.000000001,'nano micro output'!K7+'nano micro output'!K21,IF((RadS*2)<bioavai.cutoff.diameter*0.000000001,'nano micro output'!K7,0))) -> 1.4123658e-06 | W8: g.L-1
A9: Surface sea/ocean water | B9: =J9+J23+J37 -> 7.7216351e-05 | C9: =K9+K23+K37 -> 4.2873451e-05 | D9: =L9+L23+L37 -> 4.2877575e-05 | E9: =M9+M23+M37 -> 5.2149376e-05 | F9: =N9+N23+N37 -> 4.2951335e-05 | G9: g.L-1 | I9: Surface sea/ocean water | J9: ='all species output'!$M55 -> 1.7152023e-11 | K9: ='all species output'!$N55 -> 5.5037678e-15 | L9: ='all species output'!$O55 -> 3.3369045e-17 | M9: ='all species output'!$P55 -> 8.943729e-19 | N9: ='all species output'!$Q55 -> 5.2006516e-19 | O9: g.L-1 | Q9: Fresh water sediment | R9: =IF((RadP.w*2)<bioavai.cutoff.diameter*0.000000001,'nano micro output'!B8,IF((RadA.w*2)<bioavai.cutoff.diameter*0.000000001,'nano micro output'!J8+'nano micro output'!J22,IF((RadS*2)<bioavai.cutoff.diameter*0.000000001,'nano micro output'!J8,0))) -> 0.016312186 | S9: =IF((RadP.w*2)<bioavai.cutoff.diameter*0.000000001,'nano micro output'!C8,IF((RadA.w*2)<bioavai.cutoff.diameter*0.000000001,'nano micro output'!K8+'nano micro output'!K22,IF((RadS*2)<bioavai.cutoff.diameter*0.000000001,'nano micro output'!K8,0))) -> 6.1442113e-05 | W9: g.kg(w)-1
A10: Deep sea/ocean water | D10: =L10+L24+L38 -> 4.2951245e-05 | E10: =M10+M24+M38 -> 4.2877618e-05 | F10: =N10+N24+N38 -> 4.6222116e-05 | G10: g.L-1 | I10: Deep sea/ocean water | L10: ='all species output'!$O63 -> 8.6596085e-23 | M10: ='all species output'!$P63 -> 2.7167674e-24 | N10: ='all species output'!$Q63 -> 1.1778684e-24 | O10: g.L-1 | Q10: Surface sea/ocean water | R10: =IF((RadP.w*2)<bioavai.cutoff.diameter*0.000000001,'nano micro output'!B9,IF((RadA.w*2)<bioavai.cutoff.diameter*0.000000001,'nano micro output'!J9+'nano micro output'!J23,IF((RadS*2)<bioavai.cutoff.diameter*0.000000001,'nano micro output'!J9,0))) -> 7.6702589e-05 | S10: =IF((RadP.w*2)<bioavai.cutoff.diameter*0.000000001,'nano micro output'!C9,IF((RadA.w*2)<bioavai.cutoff.diameter*0.000000001,'nano micro output'!K9+'nano micro output'!K23,IF((RadS*2)<bioavai.cutoff.diameter*0.000000001,'nano micro output'!K9,0))) -> 4.2872864e-05 | T10: =IF((RadP.w*2)<bioavai.cutoff.diameter*0.000000001,'nano micro output'!D9,IF((RadA.w*2)<bioavai.cutoff.diameter*0.000000001,'nano micro output'!L9+'nano micro output'!L23,IF((RadS*2)<bioavai.cutoff.diameter*0.000000001,'nano micro output'!L9,0))) -> 4.2877042e-05 | U10: =IF((RadP.w*2)<bioavai.cutoff.diameter*0.000000001,'nano micro output'!E9,IF((RadA.w*2)<bioavai.cutoff.diameter*0.000000001,'nano micro output'!M9+'nano micro output'!M23,IF((RadS*2)<bioavai.cutoff.diameter*0.000000001,'nano micro output'!M9,0))) -> 5.2149066e-05 | V10: =IF((RadP.w*2)<bioavai.cutoff.diameter*0.000000001,'nano micro output'!F9,IF((RadA.w*2)<bioavai.cutoff.diameter*0.000000001,'nano micro output'!N9+'nano micro output'!N23,IF((RadS*2)<bioavai.cutoff.diameter*0.000000001,'nano micro output'!N9,0))) -> 4.2950263e-05 | W10: g.L-1
A11: Marine sediment | B11: =J11+J25+J39 -> 0.049368848 | C11: =K11+K25+K39 -> 0.0056411802 | D11: =L11+L25+L39 -> 0.0056896315 | E11: =M11+M25+M39 -> 0.0056374891 | F11: =N11+N25+N39 -> 0.0062310371 | G11: g.kg(w)-1 | I11: Marine sediment | J11: ='all species output'!$M71 -> 5.7140141e-17 | K11: ='all species output'!$N71 -> 6.7056302e-21 | L11: ='all species output'!$O71 -> 1.0550615e-28 | M11: ='all species output'!$P71 -> 3.3540712e-30 | N11: ='all species output'!$Q71 -> 1.4238536e-30 | O11: g.kg(w)-1 | Q11: Deep sea/ocean water | R11: =IF((RadP.w*2)<bioavai.cutoff.diameter*0.000000001,'nano micro output'!B10,IF((RadA.w*2)<bioavai.cutoff.diameter*0.000000001,'nano micro output'!J10+'nano micro output'!J24,IF((RadS*2)<bioavai.cutoff.diameter*0.000000001,'nano micro output'!J10,0))) -> 0 | S11: =IF((RadP.w*2)<bioavai.cutoff.diameter*0.000000001,'nano micro output'!C10,IF((RadA.w*2)<bioavai.cutoff.diameter*0.000000001,'nano micro output'!K10+'nano micro output'!K24,IF((RadS*2)<bioavai.cutoff.diameter*0.000000001,'nano micro output'!K10,0))) -> 0 | T11: =IF((RadP.w*2)<bioavai.cutoff.diameter*0.000000001,'nano micro output'!D10,IF((RadA.w*2)<bioavai.cutoff.diameter*0.000000001,'nano micro output'!L10+'nano micro output'!L24,IF((RadS*2)<bioavai.cutoff.diameter*0.000000001,'nano micro output'!L10,0))) -> 4.2950167e-05 | U11: =IF((RadP.w*2)<bioavai.cutoff.diameter*0.000000001,'nano micro output'!E10,IF((RadA.w*2)<bioavai.cutoff.diameter*0.000000001,'nano micro output'!M10+'nano micro output'!M24,IF((RadS*2)<bioavai.cutoff.diameter*0.000000001,'nano micro output'!M10,0))) -> 4.2877085e-05 | V11: =IF((RadP.w*2)<bioavai.cutoff.diameter*0.000000001,'nano micro output'!F10,IF((RadA.w*2)<bioavai.cutoff.diameter*0.000000001,'nano micro output'!N10+'nano micro output'!N24,IF((RadS*2)<bioavai.cutoff.diameter*0.000000001,'nano micro output'!N10,0))) -> 4.6219578e-05 | W11: g.L-1
A12: Natural soil | B12: =J12+J26+J40 -> 0.013465179 | C12: =K12+K26+K40 -> 0.00016060014 | G12: g.kg(w)-1 | I12: Natural soil | J12: ='all species output'!$M79 -> 4.8495152e-11 | K12: ='all species output'!$N79 -> 5.5824833e-13 | O12: g.kg(w)-1 | Q12: Marine sediment | R12: =IF((RadP.w*2)<bioavai.cutoff.diameter*0.000000001,'nano micro output'!B11,IF((RadA.w*2)<bioavai.cutoff.diameter*0.000000001,'nano micro output'!J11+'nano micro output'!J25,IF((RadS*2)<bioavai.cutoff.diameter*0.000000001,'nano micro output'!J11,0))) -> 0.0098486419 | S12: =IF((RadP.w*2)<bioavai.cutoff.diameter*0.000000001,'nano micro output'!C11,IF((RadA.w*2)<bioavai.cutoff.diameter*0.000000001,'nano micro output'!K11+'nano micro output'!K25,IF((RadS*2)<bioavai.cutoff.diameter*0.000000001,'nano micro output'!K11,0))) -> 0.0055953063 | T12: =IF((RadP.w*2)<bioavai.cutoff.diameter*0.000000001,'nano micro output'!D11,IF((RadA.w*2)<bioavai.cutoff.diameter*0.000000001,'nano micro output'!L11+'nano micro output'!L25,IF((RadS*2)<bioavai.cutoff.diameter*0.000000001,'nano micro output'!L11,0))) -> 0.0056053951 | U12: =IF((RadP.w*2)<bioavai.cutoff.diameter*0.000000001,'nano micro output'!E11,IF((RadA.w*2)<bioavai.cutoff.diameter*0.000000001,'nano micro output'!M11+'nano micro output'!M25,IF((RadS*2)<bioavai.cutoff.diameter*0.000000001,'nano micro output'!M11,0))) -> 0.0055958572 | V12: =IF((RadP.w*2)<bioavai.cutoff.diameter*0.000000001,'nano micro output'!F11,IF((RadA.w*2)<bioavai.cutoff.diameter*0.000000001,'nano micro output'!N11+'nano micro output'!N25,IF((RadS*2)<bioavai.cutoff.diameter*0.000000001,'nano micro output'!N11,0))) -> 0.0060326125 | W12: g.kg(w)-1
A13: Agricultural soil | B13: =J13+J27+J41 -> 0.35138929 | C13: =K13+K27+K41 -> 0.00016029066 | G13: g.kg(w)-1 | I13: Agricultural soil | J13: ='all species output'!$M87 -> 3.4075017e-10 | K13: ='all species output'!$N87 -> 1.395626e-13 | O13: g.kg(w)-1 | Q13: Natural soil | R13: =IF((RadP.w*2)<bioavai.cutoff.diameter*0.000000001,'nano micro output'!B12,IF((RadA.w*2)<bioavai.cutoff.diameter*0.000000001,'nano micro output'!J12+'nano micro output'!J26,IF((RadS*2)<bioavai.cutoff.diameter*0.000000001,'nano micro output'!J12,0))) -> 9.3613714e-06 | S13: =IF((RadP.w*2)<bioavai.cutoff.diameter*0.000000001,'nano micro output'!C12,IF((RadA.w*2)<bioavai.cutoff.diameter*0.000000001,'nano micro output'!K12+'nano micro output'!K26,IF((RadS*2)<bioavai.cutoff.diameter*0.000000001,'nano micro output'!K12,0))) -> 6.8805178e-07 | W13: g.kg(w)-1
A14: Other soil | B14: =J14+J28+J42 -> 0.013465179 | C14: =K14+K28+K42 -> 0.00016060014 | D14: =L14+L28+L42 -> 1.1555795e-06 | E14: =M14+M28+M42 -> 8.1902346e-08 | F14: =N14+N28+N42 -> 2.7040586e-08 | G14: g.kg(w)-1 | I14: Other soil | J14: ='all species output'!$M95 -> 4.8495152e-11 | K14: ='all species output'!$N95 -> 5.5824833e-13 | L14: ='all species output'!$O95 -> 3.8621356e-15 | M14: ='all species output'!$P95 -> 9.3664947e-17 | N14: ='all species output'!$Q95 -> 6.3885368e-17 | O14: g.kg(w)-1 | Q14: Agricultural soil | R14: =IF((RadP.w*2)<bioavai.cutoff.diameter*0.000000001,'nano micro output'!B13,IF((RadA.w*2)<bioavai.cutoff.diameter*0.000000001,'nano micro output'!J13+'nano micro output'!J27,IF((RadS*2)<bioavai.cutoff.diameter*0.000000001,'nano micro output'!J13,0))) -> 8.5520943e-05 | S14: =IF((RadP.w*2)<bioavai.cutoff.diameter*0.000000001,'nano micro output'!C13,IF((RadA.w*2)<bioavai.cutoff.diameter*0.000000001,'nano micro output'!K13+'nano micro output'!K27,IF((RadS*2)<bioavai.cutoff.diameter*0.000000001,'nano micro output'!K13,0))) -> 3.7802816e-07 | W14: g.kg(w)-1
Q15: Other soil | R15: =IF((RadP.w*2)<bioavai.cutoff.diameter*0.000000001,'nano micro output'!B14,IF((RadA.w*2)<bioavai.cutoff.diameter*0.000000001,'nano micro output'!J14+'nano micro output'!J28,IF((RadS*2)<bioavai.cutoff.diameter*0.000000001,'nano micro output'!J14,0))) -> 9.3613714e-06 | S15: =IF((RadP.w*2)<bioavai.cutoff.diameter*0.000000001,'nano micro output'!C14,IF((RadA.w*2)<bioavai.cutoff.diameter*0.000000001,'nano micro output'!K14+'nano micro output'!K28,IF((RadS*2)<bioavai.cutoff.diameter*0.000000001,'nano micro output'!K14,0))) -> 6.8805178e-07 | T15: =IF((RadP.w*2)<bioavai.cutoff.diameter*0.000000001,'nano micro output'!D14,IF((RadA.w*2)<bioavai.cutoff.diameter*0.000000001,'nano micro output'!L14+'nano micro output'!L28,IF((RadS*2)<bioavai.cutoff.diameter*0.000000001,'nano micro output'!L14,0))) -> 7.3784514e-08 | U15: =IF((RadP.w*2)<bioavai.cutoff.diameter*0.000000001,'nano micro output'!E14,IF((RadA.w*2)<bioavai.cutoff.diameter*0.000000001,'nano micro output'!M14+'nano micro output'!M28,IF((RadS*2)<bioavai.cutoff.diameter*0.000000001,'nano micro output'!M14,0))) -> 5.5339511e-08 | V15: =IF((RadP.w*2)<bioavai.cutoff.diameter*0.000000001,'nano micro output'!F14,IF((RadA.w*2)<bioavai.cutoff.diameter*0.000000001,'nano micro output'!N14+'nano micro output'!N28,IF((RadS*2)<bioavai.cutoff.diameter*0.000000001,'nano micro output'!N14,0))) -> 9.2203507e-09 | W15: g.kg(w)-1
I16: Species Concentration colloidal heteroagglomerates ENP <450nm (A)
J17: Regional | K17: Continental | L17: Moderate | M17: Arctic | N17: Tropical
I18: Air | J18: ='all species output'!$M16 -> 1.071866e-07 | K18: ='all species output'!$N16 -> 1.6880663e-08 | L18: ='all species output'!$O16 -> 9.9782393e-10 | M18: ='all species output'!$P16 -> 3.7626228e-10 | N18: ='all species output'!$Q16 -> 1.8690916e-10 | O18: g.m-3
I19: Fresh water lake | J19: ='all species output'!$M24 -> 0.00013520306 | K19: ='all species output'!$N24 -> 1.0141473e-06 | O19: g.L-1
I20: Fresh water lake sediment | J20: ='all species output'!$M32 -> 0.058779934 | K20: ='all species output'!$N32 -> 0.00044414641 | O20: g.kg(w)-1
I21: Fresh water | J21: ='all species output'!$M40 -> 0.00038112386 | K21: ='all species output'!$N40 -> 1.412362e-06 | O21: g.L-1
I22: Fresh water sediment | J22: ='all species output'!$M48 -> 0.016312186 | K22: ='all species output'!$N48 -> 6.1442113e-05 | O22: g.kg(w)-1
I23: Surface sea/ocean water | J23: ='all species output'!$M56 -> 7.6702571e-05 | K23: ='all species output'!$N56 -> 4.2872864e-05 | L23: ='all species output'!$O56 -> 4.2877042e-05 | M23: ='all species output'!$P56 -> 5.2149066e-05 | N23: ='all species output'!$Q56 -> 4.2950263e-05 | O23: g.L-1
I24: Deep sea/ocean water | L24: ='all species output'!$O64 -> 4.2950167e-05 | M24: ='all species output'!$P64 -> 4.2877085e-05 | N24: ='all species output'!$Q64 -> 4.6219578e-05 | O24: g.L-1
I25: Marine sediment | J25: ='all species output'!$M72 -> 0.0098486419 | K25: ='all species output'!$N72 -> 0.0055953063 | L25: ='all species output'!$O72 -> 0.0056053951 | M25: ='all species output'!$P72 -> 0.0055958572 | N25: ='all species output'!$Q72 -> 0.0060326125 | O25: g.kg(w)-1
I26: Natural soil | J26: ='all species output'!$M80 -> 9.361323e-06 | K26: ='all species output'!$N80 -> 6.8805123e-07 | O26: g.kg(w)-1
I27: Agricultural soil | J27: ='all species output'!$M88 -> 8.5520602e-05 | K27: ='all species output'!$N88 -> 3.7802802e-07 | O27: g.kg(w)-1
I28: Other soil | J28: ='all species output'!$M96 -> 9.361323e-06 | K28: ='all species output'!$N96 -> 6.8805123e-07 | L28: ='all species output'!$O96 -> 7.378451e-08 | M28: ='all species output'!$P96 -> 5.5339511e-08 | N28: ='all species output'!$Q96 -> 9.2203506e-09 | O28: g.kg(w)-1
I30: Species Concentration ENP coarse heteroagglomerates > 450nm (P)
J31: Regional | K31: Continental | L31: Moderate | M31: Arctic | N31: Tropical
I32: Air | J32: ='all species output'!$M17 -> 4.2778699e-11 | K32: ='all species output'!$N17 -> 7.0881019e-13 | L32: ='all species output'!$O17 -> 3.8459038e-15 | M32: ='all species output'!$P17 -> 2.8149152e-16 | N32: ='all species output'!$Q17 -> 3.3638617e-17 | O32: g.m-3
I33: Fresh water lake | J33: ='all species output'!$M25 -> 3.9233873e-07 | K33: ='all species output'!$N25 -> 2.8304519e-10 | O33: g.L-1
I34: Fresh water lake sediment | J34: ='all species output'!$M33 -> 0.10218661 | K34: ='all species output'!$N33 -> 7.426277e-05 | O34: g.kg(w)-1
I35: Fresh water | J35: ='all species output'!$M41 -> 6.1554803e-06 | K35: ='all species output'!$N41 -> 2.7763775e-09 | O35: g.L-1
I36: Fresh water sediment | J36: ='all species output'!$M49 -> 0.15783286 | K36: ='all species output'!$N49 -> 7.2358391e-05 | O36: g.kg(w)-1
I37: Surface sea/ocean water | J37: ='all species output'!$M57 -> 5.1376264e-07 | K37: ='all species output'!$N57 -> 5.8672433e-10 | L37: ='all species output'!$O57 -> 5.3304693e-10 | M37: ='all species output'!$P57 -> 3.1015293e-10 | N37: ='all species output'!$Q57 -> 1.071548e-09 | O37: g.L-1
I38: Deep sea/ocean water | L38: ='all species output'!$O65 -> 1.0773784e-09 | M38: ='all species output'!$P65 -> 5.3246947e-10 | N38: ='all species output'!$Q65 -> 2.5376161e-09 | O38: g.L-1
I39: Marine sediment | J39: ='all species output'!$M73 -> 0.039520206 | K39: ='all species output'!$N73 -> 4.5873906e-05 | L39: ='all species output'!$O73 -> 8.4236417e-05 | M39: ='all species output'!$P73 -> 4.163191e-05 | N39: ='all species output'!$Q73 -> 0.00019842465 | O39: g.kg(w)-1
I40: Natural soil | J40: ='all species output'!$M81 -> 0.013455817 | K40: ='all species output'!$N81 -> 0.00015991209 | O40: g.kg(w)-1
I41: Agricultural soil | J41: ='all species output'!$M89 -> 0.35130377 | K41: ='all species output'!$N89 -> 0.00015991263 | O41: g.kg(w)-1
I42: Other soil | J42: ='all species output'!$M97 -> 0.013455817 | K42: ='all species output'!$N97 -> 0.00015991209 | L42: ='all species output'!$O97 -> 1.081795e-06 | M42: ='all species output'!$P97 -> 2.6562834e-08 | N42: ='all species output'!$Q97 -> 1.7820235e-08 | O42: g.kg(w)-1

Sheet input
A1: SCENARIO- and SUBSTANCE DEFINITION
A3: PICK FROM LOOK-UP TABLES | G3: Variable Name | I3: User input | K3: Default | L3: Used | N3: Notes | O3: Equation | P3: Reference
A5: Substance | G5: ChemName | H5: default substance | J5: =IF(HLOOKUP(CaseName,CaseData,MATCH($G5,cases!$G$3:$G$1259,0)-1,FALSE)="","",HLOOKUP(CaseName,CaseData,MATCH($G5,cases!$G$3:$G$1259,0)-1,FALSE)) | K5: default substance | L5: =IF(ISBLANK(I6),IF(ISBLANK(H5),IF(J5="",K5,J5),H5),VLOOKUP(ChemRowNr,substances!A9:B4019,2,0)) -> default substance
G6: ChemRowNr | K6: =VLOOKUP(ChemName,ChemData,27,FALSE) -> 1 | L6: =IF(ISBLANK(I6),IF(J6=0,K6,J6),I6) -> 1
A8: Scenario | G8: ScenarioName | H8: default scenario | J8: =IF(HLOOKUP(CaseName,CaseData,MATCH($G8,cases!$G$3:$G$1259,0)-1,FALSE)="","",HLOOKUP(CaseName,CaseData,MATCH($G8,cases!$G$3:$G$1259,0)-1,FALSE)) | K8: default scenario | L8: =IF(ISBLANK(H8),IF(J8=0,K8,J8),H8) -> default scenario
A10: Case | G10: CaseName | H10: defaults only | J10: =IF(HLOOKUP(CaseName,CaseData,MATCH($G10,cases!$G$3:$G$1259,0)-1,FALSE)="","",HLOOKUP(CaseName,CaseData,MATCH($G10,cases!$G$3:$G$1259,0)-1,FALSE)) | K10: defaults only | L10: =IF(ISBLANK(H10),IF(ISBLANK(J10),K10,J10),H10) -> defaults only
A12: SUBSTANCE PROPERTIES nanoform | G12: Variable Name | H12: Unit | I12: User input | J12: LookUp | K12: Default | L12: Used | N12: Notes | O12: Equation | P12: Reference
B14: Radius primary ENP | G14: RadS | H14: [nm] | J14: =IF(HLOOKUP(CaseName,CaseData,MATCH($G14,cases!$G$3:$G$1259,0)-1,FALSE)="",IF(ISBLANK(VLOOKUP(ChemName,ChemData,MATCH(G14,substances!$3:$3,FALSE)-1,FALSE)),"",VLOOKUP(ChemName,ChemData,MATCH(G14,substances!$3:$3,FALSE)-1,FALSE)),HLOOKUP(CaseName,CaseData,MATCH($G14,cases!$G$3:$G$1259,0)-1,FALSE)) | K14: 10 | L14: =IF(ISBLANK(I14), IF(ISNUMBER(J14)=FALSE, K14*10^-9, J14*10^-9), I14*10^-9) -> 1e-08 | M14: m | O14: =MATCH(G14,substances!$3:$3,FALSE) -> 30
B15: Density primary ENP | G15: RhoS | H15: [kg.m-3] | J15: =IF(HLOOKUP(CaseName,CaseData,MATCH($G15,cases!$G$3:$G$1259,0)-1,FALSE)="",IF(ISBLANK(VLOOKUP(ChemName,ChemData,MATCH(G15,substances!$3:$3,FALSE)-1,FALSE)),"",VLOOKUP(ChemName,ChemData,MATCH(G15,substances!$3:$3,FALSE)-1,FALSE)),HLOOKUP(CaseName,CaseData,MATCH($G15,cases!$G$3:$G$1259,0)-1,FALSE)) | K15: =4.23*10^3 -> 4230 | L15: =IF(ISBLANK(I15), IF(ISNUMBER(J15)=FALSE, K15, J15), I15) -> 4230 | M15: kg.m-3
B16: Hamaker constant heteroagglomerate (ENP, water, SiO2) | G16: AHamakerSP.w | H16: [J] | J16: =IF(HLOOKUP(CaseName,CaseData,MATCH($G16,cases!$G$3:$G$1259,0)-1,FALSE)="",IF(ISBLANK(VLOOKUP(ChemName,ChemData,MATCH(G16,substances!$3:$3,FALSE)-1,FALSE)),"",VLOOKUP(ChemName,ChemData,MATCH(G16,substances!$3:$3,FALSE)-1,FALSE)),HLOOKUP(CaseName,CaseData,MATCH($G16,cases!$G$3:$G$1259,0)-1,FALSE)) | K16: =6.9*10^-21 -> 6.9e-21 | L16: =IF(ISBLANK(I16),IF(ISNUMBER(J16)=FALSE,K16,J16),I16) -> 6.9e-21 | M16: [J]
A18: ENGINEERED NANOPARTICLE <-> ENVIRONMENT PROPERTIES
C20: Attachment efficiencies between ENPs and natural particles in different media | G20: Variable Name | H20: Unit | I20: User input | J20: LookUp | K20: Default | L20: Used | N20: Notes
C21: Attachment Efficiency of ENPs and lake water NCs (<450 nm) | G21: AtefSA.w0 | H21: [-] | J21: =IF(HLOOKUP(CaseName,CaseData,MATCH($G21,cases!$G$3:$G$1259,0)-1,FALSE)="",IF(ISBLANK(VLOOKUP(ChemName,ChemData,MATCH(G21,substances!$3:$3,FALSE)-1,FALSE)),"",VLOOKUP(ChemName,ChemData,MATCH(G21,substances!$3:$3,FALSE)-1,FALSE)),HLOOKUP(CaseName,CaseData,MATCH($G21,cases!$G$3:$G$1259,0)-1,FALSE)) | K21: 0.1 | L21: =IF(ISBLANK(I21), IF(ISNUMBER(J21)=FALSE, K21, J21), I21) -> 0.1 | M21: -
C22: Attachment Efficiency of ENPs and lake water SPM (>450 nm) | G22: AtefSP.w0 | H22: [-] | J22: =IF(HLOOKUP(CaseName,CaseData,MATCH($G22,cases!$G$3:$G$1259,0)-1,FALSE)="",IF(ISBLANK(VLOOKUP(ChemName,ChemData,MATCH(G22,substances!$3:$3,FALSE)-1,FALSE)),"",VLOOKUP(ChemName,ChemData,MATCH(G22,substances!$3:$3,FALSE)-1,FALSE)),HLOOKUP(CaseName,CaseData,MATCH($G22,cases!$G$3:$G$1259,0)-1,FALSE)) | K22: 0.1 | L22: =IF(ISBLANK(I22), IF(ISNUMBER(J22)=FALSE, K22, J22), I22) -> 0.1 | M22: -
C23: Attachment Efficiency of ENPs and fresh water NCs (<450 nm) | G23: AtefSA.w1 | H23: [-] | J23: =IF(HLOOKUP(CaseName,CaseData,MATCH($G23,cases!$G$3:$G$1259,0)-1,FALSE)="",IF(ISBLANK(VLOOKUP(ChemName,ChemData,MATCH(G23,substances!$3:$3,FALSE)-1,FALSE)),"",VLOOKUP(ChemName,ChemData,MATCH(G23,substances!$3:$3,FALSE)-1,FALSE)),HLOOKUP(CaseName,CaseData,MATCH($G23,cases!$G$3:$G$1259,0)-1,FALSE)) | K23: 0.1 | L23: =IF(ISBLANK(I23), IF(ISNUMBER(J23)=FALSE, K23, J23), I23) -> 0.1 | M23: -
C24: Attachment Efficiency of ENPs and fresh water SPM (>450 nm) | G24: AtefSP.w1 | H24: [-] | J24: =IF(HLOOKUP(CaseName,CaseData,MATCH($G24,cases!$G$3:$G$1259,0)-1,FALSE)="",IF(ISBLANK(VLOOKUP(ChemName,ChemData,MATCH(G24,substances!$3:$3,FALSE)-1,FALSE)),"",VLOOKUP(ChemName,ChemData,MATCH(G24,substances!$3:$3,FALSE)-1,FALSE)),HLOOKUP(CaseName,CaseData,MATCH($G24,cases!$G$3:$G$1259,0)-1,FALSE)) | K24: 0.1 | L24: =IF(ISBLANK(I24), IF(ISNUMBER(J24)=FALSE, K24, J24), I24) -> 0.1 | M24: -
